I'm sorry, but an uncaught exception occurred.

While running game code:
  File "game/labels/capitulo_1/escena_01.rpy", line 45, in script
    extend "hablar con misteriosos personajes, "
  File "renpy/common/00library.rpy", line 112, in extend
    who.do_extend()
NameError: global name 'self' is not defined

-- Full Traceback ------------------------------------------------------------

Full traceback:
  File "game/labels/capitulo_1/escena_01.rpy", line 45, in script
    extend "hablar con misteriosos personajes, "
  File "F:\PROGRAMACIO\renpy-6.18.3-sdk\renpy\ast.py", line 593, in execute
    renpy.exports.say(who, what, interact=self.interact)
  File "F:\PROGRAMACIO\renpy-6.18.3-sdk\renpy\exports.py", line 999, in say
    who(what, interact=interact)
  File "renpy/common/00library.rpy", line 112, in extend
    who.do_extend()
  File "C:\Users\Gerard\projects\ReusQuest\game\model\Personaje.py", line 28, in do_extend
    getattr(store, self.nombreVariable).resolve_extend_attributes(self.predict(what))
NameError: global name 'self' is not defined

Windows-post2008Server-6.2.9200
Ren'Py 6.18.3.761
Reus Quest PreAlpha 0.0.1 0.0
