I'm sorry, but an uncaught exception occurred.

While running game code:
  File "game/labels/capitulo_1/escena_02.rpy", line 63, in script
    antagonista "pues yo creo que no"
NameError: name 'AntagonistaNombre' is not defined

-- Full Traceback ------------------------------------------------------------

Full traceback:
  File "game/labels/capitulo_1/escena_02.rpy", line 63, in script
    antagonista "pues yo creo que no"
  File "F:\PROGRAMACIO\renpy-6.18.3-sdk\renpy\ast.py", line 593, in execute
    renpy.exports.say(who, what, interact=self.interact)
  File "F:\PROGRAMACIO\renpy-6.18.3-sdk\renpy\exports.py", line 999, in say
    who(what, interact=interact)
  File "C:\Users\Gerard\projects\ReusQuest\game\model\Personaje.py", line 23, in __call__
    return getattr(store, self.nombreVariable)(what, interact=interact)
  File "F:\PROGRAMACIO\renpy-6.18.3-sdk\renpy\character.py", line 796, in __call__
    who = renpy.python.py_eval(who)
  File "F:\PROGRAMACIO\renpy-6.18.3-sdk\renpy\python.py", line 1416, in py_eval
    return eval(py_compile(source, 'eval'), globals, locals)
  File "<none>", line 1, in <module>
NameError: name 'AntagonistaNombre' is not defined

Windows-post2008Server-6.2.9200
Ren'Py 6.18.3.761
Reus Quest PreAlpha 0.0.1 0.0
